<?xml version="1.0"?>
<robot name="omni-robot-1">

  <!-------------- MATERIAL -------------->
	<material name="gray">
		<color rgba="0.7 0.7 0.7 1" />                                     # red, green, blue, transperancy
	</material>
	<material name="green">
		<color rgba="0 0.6 0 1" />
	</material>
	<material name="white">
		<color rgba="1 1 1 1" />
	</material>

  <!-------------- LINK -------------->
	<link name="base_footprint" />                                       # virtual link to world corrdinates

	<link name="base_link">
		<visual>
			<geometry>
				<box size="0.6 0.4 0.2"/>                                      # length, width, height in meters
			</geometry>
			<origin xyz="0 0 0.1" rpy ="0 0 0" />                            # xyz origin and roll-pitch-yew rotation
			<material name="green" />
		</visual>
	</link>

	<link name="lidar">
		<visual>
			<geometry>
				<cylinder radius="0.1" length="0.05" />
			</geometry>
			<origin xyz="0 0 0" rpy ="0 0 0" />
			<material name="white" />
		</visual>
	</link>

	<link name="left_wheel">
		<visual>
			<geometry>
				<cylinder radius="0.1" length="0.05" />
			</geometry>
			<origin xyz="0 0 0" rpy ="1.57 0 0" />
			<material name="gray" />
		</visual>
	</link>

	<link name="right_wheel">
		<visual>
			<geometry>
				<cylinder radius="0.1" length="0.05" />
			</geometry>
			<origin xyz="0 0 0" rpy ="1.57 0 0" />
			<material name="gray" />
		</visual>
	</link>

	<link name="caster_wheel">
		<visual>
			<geometry>
				<sphere radius="0.05" />
			</geometry>
			<origin xyz="0 0 0" rpy ="0 0 0" />
			<material name="gray" />
		</visual>
	</link>

  <!-------------- JOINTS -------------->
	<joint name="base_lidar_joint" type="fixed">
		<parent link="base_link" />
		<child link="lidar" />
		<origin xyz="0 0 0.225" rpy ="0 0 0" />                            # allways frist fix the location of the joint then the links
	</joint>

	<joint name="base_caster_wheel_joint" type="fixed">
		<parent link="base_link" />
		<child link="caster_wheel" />
		<origin xyz="0.2 0 -0.05" rpy ="0 0 0" />
	</joint>

	<joint name="base_left_wheel_joint" type="continuous">
		<parent link="base_link" />
		<child link="left_wheel" />
		<origin xyz="-0.15 0.225 0" rpy ="0 0 0" />
		<axis xyz="0 1 0" />
	</joint>

	<joint name="base_right_wheel_joint" type="continuous">
		<parent link="base_link" />
		<child link="right_wheel" />
		<origin xyz="-0.15 -0.225 0" rpy ="0 0 0" />
		<axis xyz="0 1 0" />
	</joint>

	<joint name="base_footprint_joint" type="fixed">
		<parent link="base_footprint" />
		<child link="base_link" />
		<origin xyz="0 0 0.1" rpy ="0 0 0" />
	</joint>

</robot>
